Workbook

Sheet Sheet1
A1: GRUPO A (Mexico, Sudafrica, Korea, Czechia) | J1: GRUPO B (Canada, Bosnia, Qatar, Suiza) | S1: GRUPO C (Brazil, Marruecos, Haiti, Scotland) | AB1: GRUPO D (USA, Paraguay, Australia, Turquia) | AK1: GRUPO E (Alemania, Curazao, Costa de Marfil, Ecuador) | AT1: GRUPO F (Holanda, Japon, Suecia, Tunez) | BC1: GRUPO G (Belgica, Egipto, Iran, Nueva Zelanda) | BL1: GRUPO H (España, Cabo Verde, Arabia Saudita, Uruguay) | BU1: GRUPO I (Francia, Senegal, Iraq, Noruega) | CD1: GRUPO J (Argentina, Algeria, Austria, Jordania) | CM1: GRUPO K (Portugal, Rep Dem Congo, Uzbekistan, Colombia) | CV1: GRUPO L (Inglaterra, Croacia, Ghana, Panama | DE1: ESPECIALES
A2: Mexico | C2: Sudafrica | E2: Korea | G2: Czechia | J2: Canada | L2: Bosnia | N2: Qatar | P2: Suiza | S2: Brazil | U2: Marruecos | W2: Haiti | Y2: Escocia | AB2: USA | AD2: Paraguay | AF2: Australia | AH2: Turkia | AK2: Alemania | AM2: Curazao | AO2: Costa de Marfil | AQ2: Ecuador | AT2: Holanda | AV2: Japon | AX2: Suecia | AZ2: Tunez | BC2: Belgica | BE2: Egipto | BG2: Iran | BI2: Nueva Zelanda | BL2: España | BN2: Cabo Verde | BP2: Arabia Saudita | BR2: Uruguay | BU2: Francia | BW2: Senegal | BY2: Iraq | CA2: Noruega | CD2: Argentina | CF2: Algeria | CH2: Austria | CJ2: Jordania | CM2: Portugal | CO2: Rep Congo | CQ2: Uzbekistan | CS2: Colombia | CV2: Inglaterra | CX2: Croacia | CZ2: Ghana | DB2: Panama | DE2: Especiales
A3: CARTA | B3: CANTIDAD | C3: CARTA | D3: CANTIDAD | E3: CARTA | F3: CANTIDAD | G3: CARTA | H3: CANTIDAD | J3: CARTA | K3: CANTIDAD | L3: CARTA | M3: CANTIDAD | N3: CARTA | O3: CANTIDAD | P3: CARTA | Q3: CANTIDAD | S3: CARTA | T3: CANTIDAD | U3: CARTA | V3: CANTIDAD | W3: CARTA | X3: CANTIDAD | Y3: CARTA | Z3: CANTIDAD | AB3: CARTA | AC3: CANTIDAD | AD3: CARTA | AE3: CANTIDAD | AF3: CARTA | AG3: CANTIDAD | AH3: CARTA | AI3: CANTIDAD | AK3: CARTA | AL3: CANTIDAD | AM3: CARTA | AN3: CANTIDAD | AO3: CARTA | AP3: CANTIDAD | AQ3: CARTA | AR3: CANTIDAD | AT3: CARTA | AU3: CANTIDAD | AV3: CARTA | AW3: CANTIDAD | AX3: CARTA | AY3: CANTIDAD | AZ3: CARTA | BA3: CANTIDAD | BC3: CARTA | BD3: CANTIDAD | BE3: CARTA | BF3: CANTIDAD | BG3: CARTA | BH3: CANTIDAD | BI3: CARTA | BJ3: CANTIDAD | BL3: CARTA | BM3: CANTIDAD | BN3: CARTA | BO3: CANTIDAD | BP3: CARTA | BQ3: CANTIDAD | BR3: CARTA | BS3: CANTIDAD | BU3: CARTA | BV3: CANTIDAD | BW3: CARTA | BX3: CANTIDAD | BY3: CARTA | BZ3: CANTIDAD | CA3: CARTA | CB3: CANTIDAD | CD3: CARTA | CE3: CANTIDAD | CF3: CARTA | CG3: CANTIDAD | CH3: CARTA | CI3: CANTIDAD | CJ3: CARTA | CK3: CANTIDAD | CM3: CARTA | CN3: CANTIDAD | CO3: CARTA | CP3: CANTIDAD | CQ3: CARTA | CR3: CANTIDAD | CS3: CARTA | CT3: CANTIDAD | CV3: CARTA | CW3: CANTIDAD | CX3: CARTA | CY3: CANTIDAD | CZ3: CARTA | DA3: CANTIDAD | DB3: CARTA | DC3: CANTIDAD | DE3: CARTA | DF3: CANTIDAD
A4: MEX 1 | B4: 3 | C4: RSA 1 | D4: 3 | E4: KOR 1 | F4: 5 | G4: CZE 1 | H4: 3 | J4: CAN 1 | K4: 4 | L4: BIH 1 | M4: 3 | N4: QAT 1 | O4: 2 | P4: SUI 1 | Q4: 7 | S4: BRA 1 | T4: 5 | U4: MAR 1 | V4: 7 | W4: HAI 1 | X4: 5 | Y4: SCO 1 | Z4: 4 | AB4: USA 1 | AC4: 3 | AD4: PAR 1 | AE4: 5 | AF4: AUS 1 | AG4: 3 | AH4: TUR 1 | AI4: 3 | AK4: GER 1 | AL4: 3 | AM4: CUW 1 | AN4: 4 | AO4: CIV 1 | AP4: 8 | AQ4: ECU 1 | AR4: 8 | AT4: NED 1 | AU4: 8 | AV4: JPN 1 | AW4: 2 | AX4: SWE 1 | AY4: 5 | AZ4: TUN 1 | BA4: 6 | BC4: BEL 1 | BD4: 6 | BE4: EGY 1 | BF4: 2 | BG4: IRN 1 | BH4: 7 | BI4: NZL 1 | BJ4: 2 | BL4: ESP 1 | BM4: 10 | BN4: CPV 1 | BO4: 9 | BP4: KSA 1 | BQ4: 3 | BR4: URU 1 | BS4: 5 | BU4: FRA 1 | BV4: 2 | BW4: SEN 1 | BX4: 3 | BY4: IRQ 1 | BZ4: 5 | CA4: NOR 1 | CB4: 5 | CD4: ARG 1 | CE4: 4 | CF4: ALG 1 | CG4: 3 | CH4: AUT 1 | CI4: 5 | CJ4: JOR 1 | CK4: 2 | CM4: POR 1 | CN4: 3 | CO4: COD 1 | CP4: 4 | CQ4: UZB 1 | CR4: 7 | CS4: COL 1 | CT4: 5 | CV4: ENG 1 | CW4: 5 | CX4: CRO 1 | CY4: 3 | CZ4: GHA 1 | DA4: 6 | DB4: PAN 1 | DC4: 7 | DE4: FW 00 | DF4: 7
A5: MEX 2 | B5: 4 | C5: RSA 2 | D5: 13 | E5: KOR 2 | F5: 3 | G5: CZE 2 | H5: 3 | J5: CAN 2 | K5: 7 | L5: BIH 2 | M5: 7 | N5: QAT 2 | O5: 8 | P5: SUI 2 | Q5: 6 | S5: BRA 2 | T5: 4 | U5: MAR 2 | V5: 3 | W5: HAI 2 | X5: 2 | Y5: SCO 2 | Z5: 8 | AB5: USA 2 | AC5: 7 | AD5: PAR 2 | AE5: 8 | AF5: AUS 2 | AG5: 5 | AH5: TUR 2 | AI5: 4 | AK5: GER 2 | AL5: 5 | AM5: CUW 2 | AN5: 7 | AO5: CIV 2 | AP5: 3 | AQ5: ECU 2 | AR5: 5 | AT5: NED 2 | AU5: 5 | AV5: JPN 2 | AW5: 4 | AX5: SWE 2 | AY5: 4 | AZ5: TUN 2 | BA5: 7 | BC5: BEL 2 | BD5: 5 | BE5: EGY 2 | BF5: 6 | BG5: IRN 2 | BH5: 4 | BI5: NZL 2 | BJ5: 1 | BL5: ESP 2 | BM5: 4 | BN5: CPV 2 | BO5: 3 | BP5: KSA 2 | BQ5: 11 | BR5: URU 2 | BS5: 4 | BU5: FRA 2 | BV5: 3 | BW5: SEN 2 | BX5: 9 | BY5: IRQ 2 | BZ5: 3 | CA5: NOR 2 | CB5: 3 | CD5: ARG 2 | CE5: 7 | CF5: ALG 2 | CG5: 5 | CH5: AUT 2 | CI5: 5 | CJ5: JOR 2 | CK5: 2 | CM5: POR 2 | CN5: 3 | CO5: COD 2 | CP5: 3 | CQ5: UZB 2 | CR5: 4 | CS5: COL 2 | CT5: 5 | CV5: ENG 2 | CW5: 8 | CX5: CRO 2 | CY5: 4 | CZ5: GHA 2 | DA5: 8 | DB5: PAN 2 | DC5: 6 | DE5: FW 01 | DF5: 7
A6: MEX 3 | B6: 3 | C6: RSA 3 | D6: 9 | E6: KOR 3 | F6: 3 | G6: CZE 3 | H6: 3 | J6: CAN 3 | K6: 5 | L6: BIH 3 | M6: 3 | N6: QAT 3 | O6: 7 | P6: SUI 3 | Q6: 10 | S6: BRA 3 | T6: 2 | U6: MAR 3 | V6: 5 | W6: HAI 3 | X6: 0 | Y6: SCO 3 | Z6: 12 | AB6: USA 3 | AC6: 3 | AD6: PAR 3 | AE6: 3 | AF6: AUS 3 | AG6: 7 | AH6: TUR 3 | AI6: 4 | AK6: GER 3 | AL6: 4 | AM6: CUW 3 | AN6: 2 | AO6: CIV 3 | AP6: 4 | AQ6: ECU 3 | AR6: 5 | AT6: NED 3 | AU6: 7 | AV6: JPN 3 | AW6: 6 | AX6: SWE 3 | AY6: 6 | AZ6: TUN 3 | BA6: 5 | BC6: BEL 3 | BD6: 5 | BE6: EGY 3 | BF6: 7 | BG6: IRN 3 | BH6: 5 | BI6: NZL 3 | BJ6: 8 | BL6: ESP 3 | BM6: 4 | BN6: CPV 3 | BO6: 4 | BP6: KSA 3 | BQ6: 6 | BR6: URU 3 | BS6: 4 | BU6: FRA 3 | BV6: 6 | BW6: SEN 3 | BX6: 4 | BY6: IRQ 3 | BZ6: 6 | CA6: NOR 3 | CB6: 3 | CD6: ARG 3 | CE6: 6 | CF6: ALG 3 | CG6: 4 | CH6: AUT 3 | CI6: 5 | CJ6: JOR 3 | CK6: 4 | CM6: POR 3 | CN6: 5 | CO6: COD 3 | CP6: 3 | CQ6: UZB 3 | CR6: 6 | CS6: COL 3 | CT6: 8 | CV6: ENG 3 | CW6: 2 | CX6: CRO 3 | CY6: 3 | CZ6: GHA 3 | DA6: 5 | DB6: PAN 3 | DC6: 5 | DE6: FW 02 | DF6: 9
A7: MEX 4 | B7: 7 | C7: RSA 4 | D7: 7 | E7: KOR 4 | F7: 4 | G7: CZE 4 | H7: 3 | J7: CAN 4 | K7: 3 | L7: BIH 4 | M7: 4 | N7: QAT 4 | O7: 6 | P7: SUI 4 | Q7: 6 | S7: BRA 4 | T7: 5 | U7: MAR 4 | V7: 6 | W7: HAI 4 | X7: 7 | Y7: SCO 4 | Z7: 3 | AB7: USA 4 | AC7: 7 | AD7: PAR 4 | AE7: 5 | AF7: AUS 4 | AG7: 6 | AH7: TUR 4 | AI7: 3 | AK7: GER 4 | AL7: 8 | AM7: CUW 4 | AN7: 5 | AO7: CIV 4 | AP7: 6 | AQ7: ECU 4 | AR7: 4 | AT7: NED 4 | AU7: 5 | AV7: JPN 4 | AW7: 6 | AX7: SWE 4 | AY7: 5 | AZ7: TUN 4 | BA7: 3 | BC7: BEL 4 | BD7: 2 | BE7: EGY 4 | BF7: 6 | BG7: IRN 4 | BH7: 2 | BI7: NZL 4 | BJ7: 8 | BL7: ESP 4 | BM7: 3 | BN7: CPV 4 | BO7: 5 | BP7: KSA 4 | BQ7: 3 | BR7: URU 4 | BS7: 5 | BU7: FRA 4 | BV7: 6 | BW7: SEN 4 | BX7: 7 | BY7: IRQ 4 | BZ7: 6 | CA7: NOR 4 | CB7: 1 | CD7: ARG 4 | CE7: 6 | CF7: ALG 4 | CG7: 3 | CH7: AUT 4 | CI7: 6 | CJ7: JOR 4 | CK7: 3 | CM7: POR 4 | CN7: 3 | CO7: COD 4 | CP7: 3 | CQ7: UZB 4 | CR7: 5 | CS7: COL 4 | CT7: 6 | CV7: ENG 4 | CW7: 2 | CX7: CRO 4 | CY7: 3 | CZ7: GHA 4 | DA7: 6 | DB7: PAN 4 | DC7: 3 | DE7: FW 03 | DF7: 8
A8: MEX 5 | B8: 2 | C8: RSA 5 | D8: 12 | E8: KOR 5 | F8: 2 | G8: CZE 5 | H8: 1 | J8: CAN 5 | K8: 2 | L8: BIH 5 | M8: 5 | N8: QAT 5 | O8: 2 | P8: SUI 5 | Q8: 5 | S8: BRA 5 | T8: 2 | U8: MAR 5 | V8: 6 | W8: HAI 5 | X8: 4 | Y8: SCO 5 | Z8: 9 | AB8: USA 5 | AC8: 6 | AD8: PAR 5 | AE8: 1 | AF8: AUS 5 | AG8: 3 | AH8: TUR 5 | AI8: 2 | AK8: GER 5 | AL8: 6 | AM8: CUW 5 | AN8: 5 | AO8: CIV 5 | AP8: 8 | AQ8: ECU 5 | AR8: 4 | AT8: NED 5 | AU8: 8 | AV8: JPN 5 | AW8: 4 | AX8: SWE 5 | AY8: 5 | AZ8: TUN 5 | BA8: 4 | BC8: BEL 5 | BD8: 4 | BE8: EGY 5 | BF8: 3 | BG8: IRN 5 | BH8: 5 | BI8: NZL 5 | BJ8: 6 | BL8: ESP 5 | BM8: 5 | BN8: CPV 5 | BO8: 3 | BP8: KSA 5 | BQ8: 4 | BR8: URU 5 | BS8: 3 | BU8: FRA 5 | BV8: 5 | BW8: SEN 5 | BX8: 5 | BY8: IRQ 5 | BZ8: 5 | CA8: NOR 5 | CB8: 2 | CD8: ARG 5 | CE8: 11 | CF8: ALG 5 | CG8: 4 | CH8: AUT 5 | CI8: 5 | CJ8: JOR 5 | CK8: 3 | CM8: POR 5 | CN8: 5 | CO8: COD 5 | CP8: 1 | CQ8: UZB 5 | CR8: 4 | CS8: COL 5 | CT8: 7 | CV8: ENG 5 | CW8: 4 | CX8: CRO 5 | CY8: 3 | CZ8: GHA 5 | DA8: 4 | DB8: PAN 5 | DC8: 6 | DE8: FW 04 | DF8: 4
A9: MEX 6 | B9: 5 | C9: RSA 6 | D9: 10 | E9: KOR 6 | F9: 3 | G9: CZE 6 | H9: 6 | J9: CAN 6 | K9: 8 | L9: BIH 6 | M9: 6 | N9: QAT 6 | O9: 8 | P9: SUI 6 | Q9: 4 | S9: BRA 6 | T9: 5 | U9: MAR 6 | V9: 2 | W9: HAI 6 | X9: 4 | Y9: SCO 6 | Z9: 8 | AB9: USA 6 | AC9: 3 | AD9: PAR 6 | AE9: 5 | AF9: AUS 6 | AG9: 3 | AH9: TUR 6 | AI9: 4 | AK9: GER 6 | AL9: 4 | AM9: CUW 6 | AN9: 7 | AO9: CIV 6 | AP9: 3 | AQ9: ECU 6 | AR9: 5 | AT9: NED 6 | AU9: 5 | AV9: JPN 6 | AW9: 7 | AX9: SWE 6 | AY9: 5 | AZ9: TUN 6 | BA9: 4 | BC9: BEL 6 | BD9: 5 | BE9: EGY 6 | BF9: 5 | BG9: IRN 6 | BH9: 3 | BI9: NZL 6 | BJ9: 2 | BL9: ESP 6 | BM9: 4 | BN9: CPV 6 | BO9: 2 | BP9: KSA 6 | BQ9: 8 | BR9: URU 6 | BS9: 5 | BU9: FRA 6 | BV9: 5 | BW9: SEN 6 | BX9: 13 | BY9: IRQ 6 | BZ9: 6 | CA9: NOR 6 | CB9: 3 | CD9: ARG 6 | CE9: 4 | CF9: ALG 6 | CG9: 9 | CH9: AUT 6 | CI9: 4 | CJ9: JOR 6 | CK9: 6 | CM9: POR 6 | CN9: 8 | CO9: COD 6 | CP9: 4 | CQ9: UZB 6 | CR9: 5 | CS9: COL 6 | CT9: 5 | CV9: ENG 6 | CW9: 7 | CX9: CRO 6 | CY9: 5 | CZ9: GHA 6 | DA9: 7 | DB9: PAN 6 | DC9: 5 | DE9: FW 05 | DF9: 5
A10: MEX 7 | B10: 3 | C10: RSA 7 | D10: 12 | E10: KOR 7 | F10: 0 | G10: CZE 7 | H10: 4 | J10: CAN 7 | K10: 8 | L10: BIH 7 | M10: 4 | N10: QAT 7 | O10: 7 | P10: SUI 7 | Q10: 6 | S10: BRA 7 | T10: 2 | U10: MAR 7 | V10: 8 | W10: HAI 7 | X10: 2 | Y10: SCO 7 | Z10: 8 | AB10: USA 7 | AC10: 5 | AD10: PAR 7 | AE10: 2 | AF10: AUS 7 | AG10: 8 | AH10: TUR 7 | AI10: 5 | AK10: GER 7 | AL10: 3 | AM10: CUW 7 | AN10: 8 | AO10: CIV 7 | AP10: 3 | AQ10: ECU 7 | AR10: 4 | AT10: NED 7 | AU10: 8 | AV10: JPN 7 | AW10: 6 | AX10: SWE 7 | AY10: 3 | AZ10: TUN 7 | BA10: 5 | BC10: BEL 7 | BD10: 6 | BE10: EGY 7 | BF10: 3 | BG10: IRN 7 | BH10: 4 | BI10: NZL 7 | BJ10: 6 | BL10: ESP 7 | BM10: 4 | BN10: CPV 7 | BO10: 5 | BP10: KSA 7 | BQ10: 5 | BR10: URU 7 | BS10: 6 | BU10: FRA 7 | BV10: 8 | BW10: SEN 7 | BX10: 6 | BY10: IRQ 7 | BZ10: 3 | CA10: NOR 7 | CB10: 3 | CD10: ARG 7 | CE10: 1 | CF10: ALG 7 | CG10: 8 | CH10: AUT 7 | CI10: 2 | CJ10: JOR 7 | CK10: 4 | CM10: POR 7 | CN10: 7 | CO10: COD 7 | CP10: 3 | CQ10: UZB 7 | CR10: 5 | CS10: COL 7 | CT10: 6 | CV10: ENG 7 | CW10: 1 | CX10: CRO 7 | CY10: 2 | CZ10: GHA 7 | DA10: 6 | DB10: PAN 7 | DC10: 5 | DE10: FW 06 | DF10: 5
A11: MEX 8 | B11: 5 | C11: RSA 8 | D11: 6 | E11: KOR 8 | F11: 7 | G11: CZE 8 | H11: 3 | J11: CAN 8 | K11: 3 | L11: BIH 8 | M11: 4 | N11: QAT 8 | O11: 5 | P11: SUI 8 | Q11: 4 | S11: BRA 8 | T11: 3 | U11: MAR 8 | V11: 8 | W11: HAI 8 | X11: 7 | Y11: SCO 8 | Z11: 9 | AB11: USA 8 | AC11: 7 | AD11: PAR 8 | AE11: 4 | AF11: AUS 8 | AG11: 5 | AH11: TUR 8 | AI11: 3 | AK11: GER 8 | AL11: 6 | AM11: CUW 8 | AN11: 7 | AO11: CIV 8 | AP11: 3 | AQ11: ECU 8 | AR11: 6 | AT11: NED 8 | AU11: 8 | AV11: JPN 8 | AW11: 4 | AX11: SWE 8 | AY11: 4 | AZ11: TUN 8 | BA11: 2 | BC11: BEL 8 | BD11: 2 | BE11: EGY 8 | BF11: 2 | BG11: IRN 8 | BH11: 2 | BI11: NZL 8 | BJ11: 9 | BL11: ESP 8 | BM11: 4 | BN11: CPV 8 | BO11: 6 | BP11: KSA 8 | BQ11: 5 | BR11: URU 8 | BS11: 5 | BU11: FRA 8 | BV11: 5 | BW11: SEN 8 | BX11: 10 | BY11: IRQ 8 | BZ11: 3 | CA11: NOR 8 | CB11: 1 | CD11: ARG 8 | CE11: 4 | CF11: ALG 8 | CG11: 3 | CH11: AUT 8 | CI11: 4 | CJ11: JOR 8 | CK11: 4 | CM11: POR 8 | CN11: 2 | CO11: COD 8 | CP11: 3 | CQ11: UZB 8 | CR11: 4 | CS11: COL 8 | CT11: 6 | CV11: ENG 8 | CW11: 2 | CX11: CRO 8 | CY11: 4 | CZ11: GHA 8 | DA11: 4 | DB11: PAN 8 | DC11: 4 | DE11: FW 07 | DF11: 6
A12: MEX 9 | B12: 2 | C12: RSA 9 | D12: 4 | E12: KOR 9 | F12: 3 | G12: CZE 9 | H12: 1 | J12: CAN 9 | K12: 6 | L12: BIH 9 | M12: 2 | N12: QAT 9 | O12: 8 | P12: SUI 9 | Q12: 4 | S12: BRA 9 | T12: 3 | U12: MAR 9 | V12: 5 | W12: HAI 9 | X12: 4 | Y12: SCO 9 | Z12: 7 | AB12: USA 9 | AC12: 5 | AD12: PAR 9 | AE12: 1 | AF12: AUS 9 | AG12: 6 | AH12: TUR 9 | AI12: 2 | AK12: GER 9 | AL12: 4 | AM12: CUW 9 | AN12: 6 | AO12: CIV 9 | AP12: 8 | AQ12: ECU 9 | AR12: 4 | AT12: NED 9 | AU12: 7 | AV12: JPN 9 | AW12: 2 | AX12: SWE 9 | AY12: 3 | AZ12: TUN 9 | BA12: 3 | BC12: BEL 9 | BD12: 4 | BE12: EGY 9 | BF12: 5 | BG12: IRN 9 | BH12: 4 | BI12: NZL 9 | BJ12: 5 | BL12: ESP 9 | BM12: 5 | BN12: CPV 9 | BO12: 2 | BP12: KSA 9 | BQ12: 5 | BR12: URU 9 | BS12: 4 | BU12: FRA 9 | BV12: 5 | BW12: SEN 9 | BX12: 12 | BY12: IRQ 9 | BZ12: 3 | CA12: NOR 9 | CB12: 3 | CD12: ARG 9 | CE12: 6 | CF12: ALG 9 | CG12: 4 | CH12: AUT 9 | CI12: 2 | CJ12: JOR 9 | CK12: 4 | CM12: POR 9 | CN12: 6 | CO12: COD 9 | CP12: 4 | CQ12: UZB 9 | CR12: 5 | CS12: COL 9 | CT12: 7 | CV12: ENG 9 | CW12: 4 | CX12: CRO 9 (Modric) | CY12: 2 | CZ12: GHA 9 | DA12: 3 | DB12: PAN 9 | DC12: 6 | DE12: FW 08 | DF12: 2
A13: MEX 10 | B13: 3 | C13: RSA 10 | D13: 16 | E13: KOR 10 | F13: 5 | G13: CZE 10 | H13: 6 | J13: CAN 10 | K13: 8 | L13: BIH 10 | M13: 6 | N13: QAT 10 | O13: 4 | P13: SUI 10 | Q13: 3 | S13: BRA 10 | T13: 6 | U13: MAR 10 | V13: 3 | W13: HAI 10 | X13: 4 | Y13: SCO 10 | Z13: 9 | AB13: USA 10 | AC13: 3 | AD13: PAR 10 | AE13: 5 | AF13: AUS 10 | AG13: 3 | AH13: TUR 10 | AI13: 5 | AK13: GER 10 | AL13: 7 | AM13: CUW 10 | AN13: 3 | AO13: CIV 10 | AP13: 4 | AQ13: ECU 10 | AR13: 5 | AT13: NED 10 | AU13: 4 | AV13: JPN 10 | AW13: 6 | AX13: SWE 10 | AY13: 2 | AZ13: TUN 10 | BA13: 4 | BC13: BEL 10 | BD13: 6 | BE13: EGY 10 | BF13: 4 | BG13: IRN 10 | BH13: 3 | BI13: NZL 10 | BJ13: 3 | BL13: ESP 10 | BM13: 5 | BN13: CPV 10 | BO13: 4 | BP13: KSA 10 | BQ13: 8 | BR13: URU 10 | BS13: 5 | BU13: FRA 10 | BV13: 6 | BW13: SEN 10 | BX13: 6 | BY13: IRQ 10 | BZ13: 7 | CA13: NOR 10 | CB13: 4 | CD13: ARG 10 | CE13: 7 | CF13: ALG 10 | CG13: 6 | CH13: AUT 10 | CI13: 3 | CJ13: JOR 10 | CK13: 6 | CM13: POR 10 | CN13: 8 | CO13: COD 10 | CP13: 4 | CQ13: UZB 10 | CR13: 6 | CS13: COL 10 | CT13: 3 | CV13: ENG 10 | CW13: 3 | CX13: CRO 10 | CY13: 6 | CZ13: GHA 10 | DA13: 7 | DB13: PAN 10 | DC13: 3 | DE13: FW 09 | DF13: 9
A14: MEX 11 | B14: 2 | C14: RSA 11 | D14: 13 | E14: KOR 11 | F14: 7 | G14: CZE 11 | H14: 5 | J14: CAN 11 | K14: 7 | L14: BIH 11 | M14: 6 | N14: QAT 11 | O14: 4 | P14: SUI 11 | Q14: 2 | S14: BRA 11 | T14: 3 | U14: MAR 11 | V14: 5 | W14: HAI 11 | X14: 3 | Y14: SCO 11 | Z14: 13 | AB14: USA 11 | AC14: 4 | AD14: PAR 11 | AE14: 4 | AF14: AUS 11 | AG14: 4 | AH14: TUR 11 | AI14: 4 | AK14: GER 11 | AL14: 5 | AM14: CUW 11 | AN14: 3 | AO14: CIV 11 | AP14: 4 | AQ14: ECU 11 | AR14: 3 | AT14: NED 11 | AU14: 6 | AV14: JPN 11 | AW14: 6 | AX14: SWE 11 | AY14: 5 | AZ14: TUN 11 | BA14: 2 | BC14: BEL 11 | BD14: 2 | BE14: EGY 11 | BF14: 7 | BG14: IRN 11 | BH14: 6 | BI14: NZL 11 | BJ14: 3 | BL14: ESP 11 | BM14: 3 | BN14: CPV 11 | BO14: 4 | BP14: KSA 11 | BQ14: 2 | BR14: URU 11 | BS14: 6 | BU14: FRA 11 | BV14: 9 | BW14: SEN 11 | BX14: 1 | BY14: IRQ 11 | BZ14: 4 | CA14: NOR 11 | CB14: 2 | CD14: ARG 11 | CE14: 2 | CF14: ALG 11 | CG14: 5 | CH14: AUT 11 | CI14: 4 | CJ14: JOR 11 | CK14: 3 | CM14: POR 11 | CN14: 7 | CO14: COD 11 | CP14: 4 | CQ14: UZB 11 | CR14: 3 | CS14: COL 11 | CT14: 6 | CV14: ENG 11 | CW14: 0 | CX14: CRO 11 | CY14: 3 | CZ14: GHA 11 | DA14: 3 | DB14: PAN 11 | DC14: 6 | DE14: FW 10 | DF14: 4
A15: MEX 12 | B15: 7 | C15: RSA 12 | D15: 5 | E15: KOR 12 | F15: 8 | G15: CZE 12 | H15: 4 | J15: CAN 12 | K15: 4 | L15: BIH 12 | M15: 4 | N15: QAT 12 | O15: 12 | P15: SUI 12 | Q15: 7 | S15: BRA 12 | T15: 7 | U15: MAR 12 | V15: 5 | W15: HAI 12 | X15: 8 | Y15: SCO 12 | Z15: 5 | AB15: USA 12 | AC15: 7 | AD15: PAR 12 | AE15: 4 | AF15: AUS 12 | AG15: 5 | AH15: TUR 12 | AI15: 4 | AK15: GER 12 | AL15: 5 | AM15: CUW 12 | AN15: 5 | AO15: CIV 12 | AP15: 4 | AQ15: ECU 12 | AR15: 4 | AT15: NED 12 | AU15: 7 | AV15: JPN 12 | AW15: 4 | AX15: SWE 12 | AY15: 6 | AZ15: TUN 12 | BA15: 4 | BC15: BEL 12 | BD15: 3 | BE15: EGY 12 | BF15: 8 | BG15: IRN 12 | BH15: 2 | BI15: NZL 12 | BJ15: 5 | BL15: ESP 12 | BM15: 2 | BN15: CPV 12 | BO15: 6 | BP15: KSA 12 | BQ15: 3 | BR15: URU 12 | BS15: 2 | BU15: FRA 12 | BV15: 5 | BW15: SEN 12 | BX15: 6 | BY15: IRQ 12 | BZ15: 1 | CA15: NOR 12 | CB15: 4 | CD15: ARG 12 | CE15: 5 | CF15: ALG 12 | CG15: 3 | CH15: AUT 12 | CI15: 5 | CJ15: JOR 12 | CK15: 5 | CM15: POR 12 | CN15: 2 | CO15: COD 12 | CP15: 4 | CQ15: UZB 12 | CR15: 4 | CS15: COL 12 | CT15: 5 | CV15: ENG 12 | CW15: 7 | CX15: CRO 12 | CY15: 2 | CZ15: GHA 12 | DA15: 6 | DB15: PAN 12 | DC15: 6 | DE15: FW 11 | DF15: 7
... A17: MEX 14 | B17: 2 | C17: RSA 14 | D17: 12 | E17: KOR 14 | F17: 3 | G17: CZE 14 | H17: 2 | J17: CAN 14 | K17: 7 | L17: BIH 14 | M17: 4 | N17: QAT 14 | O17: 12 | P17: SUI 14 | Q17: 4 | S17: BRA 14(VINICIUS) | T17: 5 | U17: MAR 14 | V17: 5 | W17: HAI 14 | X17: 5 | Y17: SCO 14 | Z17: 6 | AB17: USA 14 | AC17: 6 | AD17: PAR 14 | AE17: 1 | AF17: AUS 14 | AG17: 3 | AH17: TUR 14 | AI17: 3 | AK17: GER 14 | AL17: 4 | AM17: CUW 14 | AN17: 4 | AO17: CIV 14 | AP17: 7 | AQ17: ECU 14 | AR17: 6 | AT17: NED 14 | AU17: 7 | AV17: JPN 14 | AW17: 2 | AX17: SWE 14 | AY17: 4 | AZ17: TUN 14 | BA17: 6 | BC17: BEL 14 | BD17: 2 | BE17: EGY 14 | BF17: 4 | BG17: IRN 14 | BH17: 3 | BI17: NZL 14 | BJ17: 3 | BL17: ESP 14 | BM17: 6 | BN17: CPV 14 | BO17: 5 | BP17: KSA 14 | BQ17: 2 | BR17: URU 14 | BS17: 5 | BU17: FRA 14 | BV17: 7 | BW17: SEN 14 | BX17: 3 | BY17: IRQ 14 | BZ17: 3 | CA17: NOR 14 | CB17: 2 | CD17: ARG 14 | CE17: 9 | CF17: ALG 14 | CG17: 6 | CH17: AUT 14 | CI17: 7 | CJ17: JOR 14 | CK17: 6 | CM17: POR 14 | CN17: 6 | CO17: COD 14 | CP17: 3 | CQ17: UZB 14 | CR17: 5 | CS17: COL 14 (James Rodríguez) | CT17: 3 | CV17: ENG 14 | CW17: 6 | CX17: CRO 14 | CY17: 4 | CZ17: GHA 14 | DA17: 6 | DB17: PAN 14 | DC17: 7 | DE17: FW 13 | DF17: 7
A18: MEX 15 | B18: 6 | C18: RSA 15 | D18: 6 | E18: KOR 15 | F18: 5 | G18: CZE 15 | H18: 3 | J18: CAN 15 | K18: 4 | L18: BIH 15 | M18: 7 | N18: QAT 15 | O18: 3 | P18: SUI 15 | Q18: 3 | S18: BRA 15 | T18: 3 | U18: MAR 15 | V18: 6 | W18: HAI 15 | X18: 3 | Y18: SCO 15 | Z18: 6 | AB18: USA 15 | AC18: 3 | AD18: PAR 15 | AE18: 5 | AF18: AUS 15 | AG18: 4 | AH18: TUR 15 | AI18: 4 | AK18: GER 15 | AL18: 6 | AM18: CUW 15 | AN18: 5 | AO18: CIV 15 | AP18: 6 | AQ18: ECU 15 | AR18: 7 | AT18: NED 15 | AU18: 4 | AV18: JPN 15 | AW18: 6 | AX18: SWE 15 | AY18: 3 | AZ18: TUN 15 | BA18: 2 | BC18: BEL 15 | BD18: 4 | BE18: EGY 15 | BF18: 3 | BG18: IRN 15 | BH18: 2 | BI18: NZL 15 | BJ18: 6 | BL18: ESP 15(LAMINE) | BM18: 3 | BN18: CPV 15 | BO18: 0 | BP18: KSA 15 | BQ18: 7 | BR18: URU 15 | BS18: 6 | BU18: FRA 15(DEMBELE) | BV18: 8 | BW18: SEN 15 | BX18: 13 | BY18: IRQ 15 | BZ18: 7 | CA18: NOR 15(HAALAND) | CB18: 3 | CD18: ARG 15 | CE18: 4 | CF18: ALG 15 | CG18: 5 | CH18: AUT 15 | CI18: 1 | CJ18: JOR 15 | CK18: 6 | CM18: POR 15 (CR7) | CN18: 7 | CO18: COD 15 | CP18: 4 | CQ18: UZB 15 | CR18: 5 | CS18: COL 15 | CT18: 4 | CV18: ENG 15 | CW18: 3 | CX18: CRO 15 | CZ18: GHA 15 | DA18: 4 | DB18: PAN 15 | DC18: 7 | DE18: FW 14 | DF18: 10
A19: MEX 16 | B19: 8 | C19: RSA 16 | D19: 9 | E19: KOR 16 | F19: 7 | G19: CZE 16 | H19: 4 | J19: CAN 16 | K19: 9 | L19: BIH 16 | M19: 6 | N19: QAT 16 | O19: 5 | P19: SUI 16 | Q19: 1 | S19: BRA 16 | T19: 4 | U19: MAR 16 | V19: 3 | W19: HAI 16 | X19: 0 | Y19: SCO 16 | Z19: 8 | AB19: USA 16 | AC19: 3 | AD19: PAR 16 | AE19: 3 | AF19: AUS 16 | AG19: 8 | AH19: TUR 16 | AI19: 4 | AK19: GER 16 | AL19: 5 | AM19: CUW 16 | AN19: 5 | AO19: CIV 16 | AP19: 3 | AQ19: ECU 16 | AR19: 2 | AT19: NED 16 | AU19: 6 | AV19: JPN 16 | AW19: 4 | AX19: SWE 16 | AY19: 5 | AZ19: TUN 16 | BA19: 2 | BC19: BEL 16 | BD19: 3 | BE19: EGY 16 | BF19: 2 | BG19: IRN 16 | BH19: 4 | BI19: NZL 16 | BJ19: 7 | BL19: ESP 16 | BM19: 5 | BN19: CPV 16 | BO19: 5 | BP19: KSA 16 | BQ19: 2 | BR19: URU 16 | BS19: 9 | BU19: FRA 16 | BV19: 4 | BW19: SEN 16 | BX19: 9 | BY19: IRQ 16 | BZ19: 4 | CA19: NOR 16 | CB19: 2 | CD19: ARG 16 | CE19: 2 | CF19: ALG 16 | CG19: 6 | CH19: AUT 16 | CI19: 5 | CJ19: JOR 16 | CK19: 2 | CM19: POR 16 | CN19: 7 | CO19: COD 16 | CP19: 4 | CQ19: UZB 16 | CR19: 2 | CS19: COL 16 | CT19: 5 | CV19: ENG 16 | CW19: 6 | CX19: CRO 16 | CY19: 3 | CZ19: GHA 16 | DA19: 2 | DB19: PAN 16 | DC19: 6 | DE19: FW 15 | DF19: 9
A20: MEX 17 | B20: 5 | C20: RSA 17 | D20: 3 | E20: KOR 17 | F20: 19 | G20: CZE 17 | H20: 4 | J20: CAN 17 | K20: 3 | L20: BIH 17 | M20: 3 | N20: QAT 17 | O20: 5 | P20: SUI 17 | Q20: 7 | S20: BRA 17 | T20: 7 | U20: MAR 17 | V20: 3 | W20: HAI 17 | X20: 8 | Y20: SCO 17 | Z20: 5 | AB20: USA 17 | AC20: 3 | AD20: PAR 17 | AE20: 3 | AF20: AUS 17 | AG20: 5 | AH20: TUR 17 | AI20: 5 | AK20: GER 17 | AL20: 8 | AM20: CUW 17 | AN20: 5 | AO20: CIV 17 | AP20: 5 | AQ20: ECU 17 | AR20: 5 | AT20: NED 17 | AU20: 1 | AV20: JPN 17 | AW20: 5 | AX20: SWE 17 | AY20: 4 | AZ20: TUN 17 | BA20: 5 | BC20: BEL 17 | BD20: 6 | BE20: EGY 17 | BF20: 8 | BG20: IRN 17 | BH20: 2 | BI20: NZL 17 | BJ20: 5 | BL20: ESP 17 | BM20: 5 | BN20: CPV 17 | BO20: 6 | BP20: KSA 17 | BQ20: 3 | BR20: URU 17 | BS20: 5 | BU20: FRA 17 | BV20: 7 | BW20: SEN 17 | BX20: 3 | BY20: IRQ 17 | BZ20: 4 | CA20: NOR 17 | CB20: 4 | CD20: ARG 17(MESSI) | CE20: 5 | CF20: ALG 17 | CG20: 3 | CH20: AUT 17 | CI20: 5 | CJ20: JOR 17 | CK20: 3 | CM20: POR 17 | CN20: 3 | CO20: COD 17 | CP20: 3 | CQ20: UZB 17 | CR20: 3 | CS20: COL 17 | CT20: 5 | CV20: ENG 17 | CW20: 2 | CX20: CRO 17 | CY20: 6 | CZ20: GHA 17 | DA20: 6 | DB20: PAN 17 | DC20: 7 | DE20: FW 16 | DF20: 5
A21: MEX 18 | B21: 8 | C21: RSA 18 | D21: 4 | E21: KOR 18 | F21: 3 | G21: CZE 18 | H21: 4 | J21: CAN 18 | K21: 3 | L21: BIH 18 | M21: 3 | N21: QAT 18 | O21: 6 | P21: SUI 18 | Q21: 4 | S21: BRA 18 | T21: 5 | U21: MAR 18 | V21: 4 | W21: HAI 18 | X21: 5 | Y21: SCO 18 | Z21: 5 | AB21: USA 18 | AC21: 5 | AD21: PAR 18 | AE21: 6 | AF21: AUS 18 | AG21: 5 | AH21: TUR 18 | AI21: 3 | AK21: GER 18 | AL21: 4 | AM21: CUW 18 | AN21: 5 | AO21: CIV 18 | AP21: 9 | AQ21: ECU 18 | AR21: 5 | AT21: NED 18 | AU21: 2 | AV21: JPN 18 | AW21: 2 | AX21: SWE 18 | AY21: 2 | AZ21: TUN 18 | BA21: 4 | BC21: BEL 18 | BD21: 1 | BE21: EGY 18 | BF21: 4 | BG21: IRN 18 | BH21: 4 | BI21: NZL 18 | BJ21: 4 | BL21: ESP 18 | BM21: 7 | BN21: CPV 18 | BO21: 5 | BP21: KSA 18 | BQ21: 3 | BR21: URU 18 | BS21: 3 | BU21: FRA 18 | BV21: 5 | BW21: SEN 18 | BX21: 7 | BY21: IRQ 18 | BZ21: 5 | CA21: NOR 18 | CB21: 2 | CD21: ARG 18 | CE21: 10 | CF21: ALG 18 | CG21: 6 | CH21: AUT 18 | CI21: 4 | CJ21: JOR 18 | CK21: 6 | CM21: POR 18 | CN21: 6 | CO21: COD 18 | CP21: 4 | CQ21: UZB 18 | CR21: 4 | CS21: COL 18 | CT21: 3 | CV21: ENG 18 | CW21: 4 | CX21: CRO 18 | CY21: 3 | CZ21: GHA 18 | DA21: 5 | DB21: PAN 18 | DC21: 3 | DE21: FW 17 | DF21: 1
A22: MEX 19 | B22: 5 | C22: RSA 19 | D22: 13 | E22: KOR 19 | F22: 4 | G22: CZE 19 | H22: 5 | J22: CAN 19 | K22: 3 | L22: BIH 19 | M22: 3 | N22: QAT 19 | O22: 2 | P22: SUI 19 | Q22: 1 | S22: BRA 19(RAFINHA) | T22: 2 | U22: MAR 19 | V22: 7 | W22: HAI 19 | X22: 4 | Y22: SCO 19 | Z22: 8 | AB22: USA 19 | AC22: 6 | AD22: PAR 19 | AE22: 3 | AF22: AUS 19 | AG22: 3 | AH22: TUR 19 | AI22: 5 | AK22: GER 19 | AL22: 6 | AM22: CUW 19 | AN22: 4 | AO22: CIV 19 | AP22: 7 | AQ22: ECU 19 | AR22: 6 | AT22: NED 19 | AU22: 2 | AV22: JPN 19 | AW22: 3 | AX22: SWE 19 | AY22: 3 | AZ22: TUN 19 | BA22: 3 | BC22: BEL 19 | BD22: 5 | BE22: EGY 19 | BF22: 2 | BG22: IRN 19 | BH22: 3 | BI22: NZL 19 | BJ22: 6 | BL22: ESP 19 | BM22: 5 | BN22: CPV 19 | BO22: 2 | BP22: KSA 19 | BQ22: 8 | BR22: URU 19 | BS22: 7 | BU22: FRA 19 | BV22: 9 | BW22: SEN 19 | BX22: 15 | BY22: IRQ 19 | BZ22: 3 | CA22: NOR 19 | CB22: 8 | CD22: ARG 19(JULIAN) | CE22: 6 | CF22: ALG 19 | CG22: 8 | CH22: AUT 19 | CI22: 2 | CJ22: JOR 19 | CK22: 6 | CM22: POR 19 | CN22: 5 | CO22: COD 19 | CP22: 2 | CQ22: UZB 19 | CR22: 4 | CS22: COL 19 | CT22: 6 | CV22: ENG 19 | CW22: 3 | CX22: CRO 19 | CY22: 4 | CZ22: GHA 19 | DA22: 8 | DB22: PAN 19 | DC22: 7 | DE22: FW 18 | DF22: 7
A23: MEX 20 | B23: 7 | C23: RSA 20 | D23: 16 | E23: KOR 20 | F23: 5 | G23: CZE 20 | H23: 5 | J23: CAN 20 | K23: 9 | L23: BIH 20 | M23: 3 | N23: QAT 20 | O23: 4 | P23: SUI 20 | Q23: 2 | S23: BRA 20 | T23: 6 | U23: MAR 20 | V23: 2 | W23: HAI 20 | X23: 1 | Y23: SCO 20 | Z23: 7 | AB23: USA 20 | AC23: 4 | AD23: PAR 20 | AE23: 5 | AF23: AUS 20 | AG23: 7 | AH23: TUR 20 | AI23: 5 | AK23: GER 20 | AL23: 3 | AM23: CUW 20 | AN23: 4 | AO23: CIV 20 | AP23: 6 | AQ23: ECU 20 | AR23: 3 | AT23: NED 20 | AU23: 3 | AV23: JPN 20 | AW23: 3 | AX23: SWE 20 | AY23: 1 | AZ23: TUN 20 | BA23: 3 | BC23: BEL 20 | BD23: 2 | BE23: EGY 20 | BF23: 3 | BG23: IRN 20 | BH23: 5 | BI23: NZL 20 | BJ23: 7 | BL23: ESP 20 | BM23: 2 | BN23: CPV 20 | BO23: 5 | BP23: KSA 20 | BQ23: 3 | BR23: URU 20 | BS23: 7 | BU23: FRA 20(MBAPPE) | BV23: 5 | BW23: SEN 20 | BX23: 9 | BY23: IRQ 20 | BZ23: 4 | CA23: NOR 20 | CB23: 6 | CD23: ARG 20 | CE23: 2 | CF23: ALG 20 | CG23: 5 | CH23: AUT 20 | CI23: 4 | CJ23: JOR 20 | CK23: 4 | CM23: POR 20 | CN23: 2 | CO23: COD 20 | CP23: 2 | CQ23: UZB 20 | CR23: 4 | CS23: COL 20 | CT23: 2 | CV23: ENG 20 | CW23: 6 | CX23: CRO 20 | CY23: 3 | CZ23: GHA 20 | DA23: 5 | DB23: PAN 20 | DC23: 6 | DE23: FW 19 | DF23: 6
A24: TOTAL | B24: =SUM(B4:B23) -> 94 | C24: TOTAL | D24: =SUM(D4:D23) -> 176 | E24: TOTAL | F24: =SUM(F4:F23) -> 98 | G24: TOTAL | H24: =SUM(H4:H23) -> 71 | J24: TOTAL | K24: =SUM(K4:K23) -> 106 | L24: TOTAL | M24: =SUM(M4:M23) -> 86 | N24: TOTAL | O24: =SUM(O4:O23) -> 113 | P24: TOTAL | Q24: =SUM(Q4:Q23) -> 89 | S24: TOTAL | T24: =SUM(T4:T23) -> 83 | U24: TOTAL | V24: =SUM(V4:V23) -> 97 | W24: TOTAL | X24: =SUM(X4:X23) -> 78 | Y24: TOTAL | Z24: =SUM(Z4:Z23) -> 146 | AB24: TOTAL | AC24: =SUM(AC4:AC23) -> 93 | AD24: TOTAL | AE24: =SUM(AE4:AE23) -> 78 | AF24: TOTAL | AG24: =SUM(AG4:AG23) -> 97 | AH24: TOTAL | AI24: =SUM(AI4:AI23) -> 75 | AK24: TOTAL | AL24: =SUM(AL4:AL23) -> 102 | AM24: TOTAL | AN24: =SUM(AN4:AN23) -> 99 | AO24: TOTAL | AP24: =SUM(AP4:AP23) -> 106 | AQ24: TOTAL | AR24: =SUM(AR4:AR23) -> 96 | AT24: TOTAL | AU24: =SUM(AU4:AU23) -> 107 | AV24: TOTAL | AW24: =SUM(AW4:AW23) -> 84 | AX24: TOTAL | AY24: =SUM(AY4:AY23) -> 78 | AZ24: TOTAL | BA24: =SUM(BA4:BA23) -> 79 | BC24: TOTAL | BD24: =SUM(BD4:BD23) -> 77 | BE24: TOTAL | BF24: =SUM(BF4:BF23) -> 88 | BG24: TOTAL | BH24: =SUM(BH4:BH23) -> 75 | BI24: TOTAL | BJ24: =SUM(BJ4:BJ23) -> 100 | BL24: TOTAL | BM24: =SUM(BM4:BM23) -> 89 | BN24: TOTAL | BO24: =SUM(BO4:BO23) -> 85 | BP24: TOTAL | BQ24: =SUM(BQ4:BQ23) -> 96 | BR24: TOTAL | BS24: =SUM(BS4:BS23) -> 100 | BU24: TOTAL | BV24: =SUM(BV4:BV23) -> 114 | BW24: TOTAL | BX24: =SUM(BX4:BX23) -> 145 | BY24: TOTAL | BZ24: =SUM(BZ4:BZ23) -> 87 | CA24: TOTAL | CB24: =SUM(CB4:CB23) -> 66 | CD24: TOTAL | CE24: =SUM(CE4:CE23) -> 107 | CF24: TOTAL | CG24: =SUM(CG4:CG23) -> 101 | CH24: TOTAL | CI24: =SUM(CI4:CI23) -> 83 | CJ24: TOTAL | CK24: =SUM(CK4:CK23) -> 84 | CM24: TOTAL | CN24: =SUM(CN4:CN23) -> 99 | CO24: TOTAL | CP24: =SUM(CP4:CP23) -> 66 | CQ24: TOTAL | CR24: =SUM(CR4:CR23) -> 88 | CS24: TOTAL | CT24: =SUM(CT4:CT23) -> 101 | CV24: TOTAL | CW24: =SUM(CW4:CW23) -> 79 | CX24: TOTAL | CY24: =SUM(CY4:CY23) -> 66 | CZ24: TOTAL | DA24: =SUM(DA4:DA23) -> 104 | DB24: TOTAL | DC24: =SUM(DC4:DC23) -> 111 | DE24: TOTAL | DF24: =SUM(DF4:DF23) -> 126
A27: Suma totales | B27: =sum(B24,D24,F24,H24,K24,M24,O24,Q24,S24,U24,W24,Y24,AB24,AD24,AF24,AH24,AL24,AN24,AP24,AR24,AU24,AW24,AY24,BA24,BD24,BF24,BH24,BJ24,BM24,BO24,BQ24,BS24,BV24,BX24,BZ24,CB24,CE24,CG24,CI24,CK24,CN24,CP24,CR24,CT24,CW24,CY24,DA24,DC24,DF24) -> 3921 | AE27: *
B33: Parametros | G33: Postales | M33: Inversion | N33: Cant | O33: Precio | P33: Total | Q33: Mitad
B34: Bajo | C34: 3 | G34: Tipo | H34: Cantidad | I34: Precio | J34: Dinero | M34: Cubos | N34: 10 | O34: 563300 | P34: =N34*O34 -> 5633000 | Q34: =P34/2 -> 2816500
B35: Medio | C35: 4 | D35: 5 | G35: Normales | H35: =((((sum(B4:B23, D4:D23, F4:F23, H4:H23, K4:K23, M4:M23, O4:O23, Q4:Q23, T4:T16, T18:T21, T23 , V4:V23, X4:X23, Z4:Z23, AC4:AC23, AE4:AE23, AG4:AG23, AI4:AI23, AL4:AL23, AN4:AN23, AP4:AP23, AR4:AR23, AU4:AU23, AW4:AW23, AY4:AY23, BA4:BA23, BD4:BD23, BF4:BF23, BH4:BH23, BJ4:BJ23, BM4:BM17, BM19:BM23, BO4:BO23, BQ4:BQ23, BS4:BS23, BV4:BV17, BV19:BV22, BX4:BX23, BZ4:BZ23, CB4:CB23, CE4:CE19, CE21, CE23, CG4:CG23, CI4:CI23, CK4:CK23, CN4:CN17, CN19:CN23, CP4:CP23, CR4:CR23, CT4:CT23, CW4:CW23, CY4:CY11, CY13:CY23, DA4:DA23, DC4:DC23, DF4:DF23)-SUM(B13,D13,F13,H13,K13,M13,O13,Q13,T13,V13,X13,Z13,AC13,AE13,AG13,AI13,AL13,AN13,AP13,AR13,AU13,AW13,AY13,BA13,BD13,BF13,BH13,BJ13,BM13,BO13,BQ13,BS13,BV13,BX13,BZ13,CB13,CE13,CG13,CI13,CK13,CN13,CP13,CR13,CT13,CW13,CY13,DA13,DC13))-sum(B4,D4,F4,H4,K4,M4,O4,Q4,T4,V4,X4,Z4,AC4,AE4,AG4,AI4,AL4,AN4,AP4,AR4,AU4,AW4,AY4,BA4,BD4,BF4,BH4,BJ4,BM4,BO4,BQ4,BS4,BV4,BX4,BZ4,CB4,CE4,CG4,CI4,CK4,CN4,CP4,CR4,CT4,CW4,CY4,DA4,DC4))-sum(T17,T22,BV18,CE22,CY12))-sum(BM18,BV23))-sum(CE20,CN18) -> 4113 | I35: 100 | J35: =I35*H35 -> 411300
B36: Alto | C36: 5 | D36: 9 | G36: Normales real | H36: =B27-sum(H37:H43) -> 3283 | I36: 150 | J36: =I36*H36 -> 492450
B37: Extremo | C37: 10 | G37: Escudos | H37: =sum(B4,D4,F4,H4,K4,M4,O4,Q4,T4,V4,X4,Z4,AC4,AE4,AG4,AI4,AL4,AN4,AP4,AR4,AU4,AW4,AY4,BA4,BD4,BF4,BH4,BJ4,BM4,BO4,BQ4,BS4,BV4,BX4,BZ4,CB4,CE4,CG4,CI4,CK4,CN4,CP4,CR4,CT4,CW4,CY4,DA4,DC4) -> 222 | I37: 500 | J37: =I37*H37 -> 111000
G38: Seleccion | H38: =sum(B13,D13,F13,H13,K13,M13,O13,Q13,T13,V13,X13,Z13,AC13,AE13,AG13,AI13,AL13,AN13,AP13,AR13,AU13,AW13,AY13,BA13,BD13,BF13,BH13,BJ13,BM13,BO13,BQ13,BS13,BV13,BX13,BZ13,CB13,CE13,CG13,CI13,CK13,CN13,CP13,CR13,CT13,CW13,CY13,DA13,DC13) -> 247 | I38: 200 | J38: =I38*H38 -> 49400
G39: FW | H39: =SUM(DF5:DF23) -> 119 | I39: 500 | J39: =I39*H39 -> 59500
G40: "00" | H40: =DF4 -> 7 | I40: 1500 | J40: =I40*H40 -> 10500
G41: Osumane,Raphinha,Modric,Vinicius,Julian,Haaland | H41: =sum(T17,T22,BV18,CE22,CY12) -> 23 | I41: 1500 | J41: =I41*H41 -> 34500
G42: Lamine,Mbappe | H42: =sum(BM18,BV23) -> 8 | I42: 2500 | J42: =I42*H42 -> 20000
G43: Messi, CR7 | H43: =sum(CE20,CN18) -> 12 | I43: 3500 | J43: =I43*H43 -> 42000
G44: Total | H44: =SUM(H36:H43) -> 3921 | J44: =SUM(J36:J43) -> 819350
P58: -

Sheet Sheet3
B2: Tipo | C2: Precio
B3: Normales | C3: 150
B4: Escudos | C4: 500
B5: Seleccion | C5: 200
B6: FW | C6: 500
B7: "00" | C7: 3000
B8: Osumane, Raphinha, Modric, Vinicius | C8: 1500
B9: Lamine, Mbappe | C9: 2000
B10: Messi, CR7 | C10: 3500

Sheet Cant cartas bajas
B2: Cant Bajas
A4: Mexico | B4: =SUMIF(Sheet1!B$4:B$23, "<=3",$N$4:$N$23) -> 8 | N4: 1
A5: Sudafrica | B5: =SUMIF(Sheet1!D$4:D$23, "<=3",$N$4:$N$23) -> 3 | N5: 1
A6: Korea | B6: =SUMIF(Sheet1!F$4:F$23, "<=3",$N$4:$N$23) -> 9 | N6: 1
A7: Czechia | B7: =SUMIF(Sheet1!H$4:H$23, "<=3",$N$4:$N$23) -> 10 | N7: 1
N8: 1
N9: 1
A10: Mexico | B10: =SUMIF(Sheet1!B$4:B$23, "<=3",$N$4:$N$23) -> 8 | N10: 1
A11: Sudafrica | B11: =SUMIF(Sheet1!D$4:D$23, "<=3",$N$4:$N$23) -> 3 | N11: 1
A12: Korea | B12: =SUMIF(Sheet1!F$4:F$23, "<=3",$N$4:$N$23) -> 9 | N12: 1
A13: Czechia | B13: =SUMIF(Sheet1!H$4:H$23, "<=3",$N$4:$N$23) -> 10 | N13: 1
N14: 1
N15: 1
A16: Mexico | B16: =SUMIF(Sheet1!B$4:B$23, "<=3",$N$4:$N$23) -> 8 | N16: 1
A17: Sudafrica | B17: =SUMIF(Sheet1!D$4:D$23, "<=3",$N$4:$N$23) -> 3 | N17: 1
A18: Korea | B18: =SUMIF(Sheet1!F$4:F$23, "<=3",$N$4:$N$23) -> 9 | N18: 1
A19: Czechia | B19: =SUMIF(Sheet1!H$4:H$23, "<=3",$N$4:$N$23) -> 10 | N19: 1
N20: 1
N21: 1
A22: Mexico | B22: =SUMIF(Sheet1!B$4:B$23, "<=3",$N$4:$N$23) -> 8 | N22: 1
A23: Sudafrica | B23: =SUMIF(Sheet1!D$4:D$23, "<=3",$N$4:$N$23) -> 3 | N23: 1
A24: Korea | B24: =SUMIF(Sheet1!F$4:F$23, "<=3",$N$4:$N$23) -> 9
A25: Czechia | B25: =SUMIF(Sheet1!H$4:H$23, "<=3",$N$4:$N$23) -> 10
A28: Mexico | B28: =SUMIF(Sheet1!B$4:B$23, "<=3",$N$4:$N$23) -> 8
A29: Sudafrica | B29: =SUMIF(Sheet1!D$4:D$23, "<=3",$N$4:$N$23) -> 3
A30: Korea | B30: =SUMIF(Sheet1!F$4:F$23, "<=3",$N$4:$N$23) -> 9
A31: Czechia | B31: =SUMIF(Sheet1!H$4:H$23, "<=3",$N$4:$N$23) -> 10
A34: Mexico | B34: =SUMIF(Sheet1!B$4:B$23, "<=3",$N$4:$N$23) -> 8
A35: Sudafrica | B35: =SUMIF(Sheet1!D$4:D$23, "<=3",$N$4:$N$23) -> 3
A36: Korea | B36: =SUMIF(Sheet1!F$4:F$23, "<=3",$N$4:$N$23) -> 9
A37: Czechia | B37: =SUMIF(Sheet1!H$4:H$23, "<=3",$N$4:$N$23) -> 10
A40: Mexico | B40: =SUMIF(Sheet1!B$4:B$23, "<=3",$N$4:$N$23) -> 8
A41: Sudafrica | B41: =SUMIF(Sheet1!D$4:D$23, "<=3",$N$4:$N$23) -> 3
A42: Korea | B42: =SUMIF(Sheet1!F$4:F$23, "<=3",$N$4:$N$23) -> 9
A43: Czechia | B43: =SUMIF(Sheet1!H$4:H$23, "<=3",$N$4:$N$23) -> 10
A46: Mexico | B46: =SUMIF(Sheet1!B$4:B$23, "<=3",$N$4:$N$23) -> 8
A47: Sudafrica | B47: =SUMIF(Sheet1!D$4:D$23, "<=3",$N$4:$N$23) -> 3
A48: Korea | B48: =SUMIF(Sheet1!F$4:F$23, "<=3",$N$4:$N$23) -> 9
A49: Czechia | B49: =SUMIF(Sheet1!H$4:H$23, "<=3",$N$4:$N$23) -> 10
A52: Mexico | B52: =SUMIF(Sheet1!B$4:B$23, "<=3",$N$4:$N$23) -> 8
...
